Workbook
Name cvv: '[1]comparativo varejo'!$A$2
Name frv: '[1]comparativo varejo'!$C$2
Name sdv: '[1]comparativo varejo'!$B$2

Sheet Em andamento
D2: TRAÇO EXPERIMENTAL DE LABORATÓRIO
D4: 1. Identificação
D5: ESTUDO/CLIENTE: | I5: DATA: | J5: 44857 | M5: DOSAGEM Nº:
D6: TRAÇO: | G6: APLICAÇÃO: | K6: CENTRAL:
D7: 2. Características do concreto / parâmetros de dosagem
D8: fck | E8: Sd | F8: Fc28d (Mpa) | G8: abatimento (mm) | H8: água (l/m3) | I8: consumo (kg/m3) | J8: a/c | K8: Targ.vol. (%) | L8: Tar (%) | M8: D Max | N8: Eci (Gpa | O8: Tipo de Lançamento
D9: 35 | E9: 4 | F9: 35 | G9: 100+-20 | H9: 205 | I9: 350 | J9: =SUM(H9/I9) -> 0.58571429 | K9: 0.465 | L9: 0.03 | M9: 19.1 | N9: 28 | O9: Bombéavel
D10: 3. Materiais utilizados
D11: material | F11: descrição | H11: Fornecedor | J11: tipo/classe | K11: M. Finura | L11: M. Especidica
D12: cimento | F12: CIMENTO | H12: CAUÊ | J12: CPII E 40 | K12: 4.35 | L12: 3
D13: aglom.2 | L13: 1
D14: 3.3 ag.miúdo 1 | F14: AREIA DE QUARTZO | H14: C131 BARÃO | J14: AQFINA | L14: 2.63
D15: ag.miúdo 2 | F15: AREIA DE QUARTZO | H15: ITAPORANGA | J15: AQGROSSA | L15: 2.7
D16: ag.miúdo 3 | L16: 1
D17: ag.graúdo 1 | F17: Pedrisco | H17: GALVANI | J17: Brita 0 | L17: 2.69
D18: ag.graúdo 2 | F18: Brita 1 | H18: GALVANI | J18: Brita 1 | L18: 2.69
D19: ag.graúdo 3 | L19: 1
D20: aditivo 1 | F20: Tec Mult 828LF | H20: Rheoset | J20: TM828LF | L20: 1.18
D21: aditivo 2 | F21: Tec Flow 41N | H21: Rheoset | J21: TF41N | L21: 1.1
D22: aditivo 3 | L22: 1
D23: adição 1 | L23: 1
D24: adição 2 | L24: 1
D25: 4. Traços
D26: DOSAGEM PARA 1 m3 - 1000 litros | J26: DOSAGEM PARA 1 BETONADA DE | N26: 25 | O26: litros
D27: material | F27: traço inicial | G27: t.unitário | H27: t.unit.cor. | I27: traço corr. | J27: material | L27: massa seca (kg) | M27: h(%) | N27: mat. corrig | O27: correção
D28: cimento | F28: =I9 -> 350 | G28: =F28/I9 -> 1 | H28: =IF(H9=0," ",($L28+$O28)/($L$28+$O$28)) -> 1 | I28: =IF(H9=0," ",B25-I29) -> 0 | J28: cimento | K28: =IF($J12=0," ",$J12) -> CPII E 40 | L28: =IF(H9=0," ",$F28*($N$26/1000)) -> 8.75
D29: aglom.2 | E29: =F29/F28 -> 0.042857143 | F29: 15 | I29: =IF(H9=0," ",B25*E29) -> 0 | J29: aglom.2 | K29: =IF($J13=0," ",$J13) | L29: =IF(H9=0," ",$F29*($N$26/1000)) -> 0.375
D30: ag.miúdo 1 | E30: =SUM($F$30/($F$30+$F$31+$F$32)) -> 0.67522659 | F30: 447 | G30: =IF(H9=0," ",$F30/($F$28+$F$29)) -> 1.2246575 | H30: =IF(H9=0," ",(($L30+($O30/(1+$M30)))/($L$28+$O$28+$L$29+$O$29))) -> 1.2246575 | I30: =IF(H9=0," ",$H30*$B$25) -> 0 | J30: ag.miúdo 1 | K30: =IF($J14=0," ",$J14) -> AQFINA | L30: =IF(H9=0," ",$F30*($N$26/1000)) -> 11.175 | M30: 0 | N30: =IF($M30=" "," ",$L30*(1+$M30)) -> 11.175
D31: ag.miúdo 2 | E31: =SUM($F$31/($F$30+$F$31+$F$32)) -> 0.32477341 | F31: 215 | G31: =IF(H9=0," ",$F31/($F$28+$F$29)) -> 0.5890411 | H31: =IF(H9=0," ",(($L31+($O31/(1+$M31)))/($L$28+$O$28+$L$29+$O$29))) -> 0.5890411 | I31: =IF(H9=0," ",$H31*$B$25) -> 0 | J31: ag.miúdo 2 | K31: =IF($J15=0," ",$J15) -> AQGROSSA | L31: =IF(H9=0," ",$F31*($N$26/1000)) -> 5.375 | M31: 0 | N31: =IF($M31=" "," ",$L31*(1+$M31)) -> 5.375
D32: ag.miúdo 3 | E32: =SUM($F$32/($F$30+$F$31+$F$32)) -> 0 | F32: 0 | G32: =IF(H9=0," ",$F32/($F$28+$F$29)) -> 0 | H32: =IF(H9=0," ",(($L32+($O32/(1+$M32)))/($L$28+$O$28+$L$29+$O$29))) -> 0 | I32: =IF(H9=0," ",$H32*$B$25) -> 0 | J32: ag.miúdo 3 | L32: =IF(H9=0," ",$F32*($N$26/1000)) -> 0
D33: ag.graúdo 1 | F33: 250 | G33: =IF(H9=0," ",$F33/($F$28+$F$29)) -> 0.68493151 | H33: =IF(H9=0," ",(($L33+($O33/(1+$M33)))/($L$28+$O$28+$L$29+$O$29))) -> 0.68493151 | I33: =IF(H9=0," ",$H33*$B$25) -> 0 | J33: ag.graúdo 1 | K33: =IF($J17=0," ",$J17) -> Brita 0 | L33: =IF(H9=0," ",$F33*($N$26/1000)) -> 6.25 | S33: comentários sobre o aspecto
D34: ag.graúdo 2 | F34: 850 | G34: =IF(H9=0," ",$F34/($F$28+$F$29)) -> 2.3287671 | H34: =IF(H9=0," ",(($L34+($O34/(1+$M34)))/($L$28+$O$28+$L$29+$O$29))) -> 2.3287671 | I34: =IF(H9=0," ",$H34*$B$25) -> 0 | J34: ag.graúdo 2 | K34: =IF($J18=0," ",$J18) -> Brita 1 | L34: =IF(H9=0," ",$F34*($N$26/1000)) -> 21.25 | S34: DET. MASSA ESP. NO ESTADO FRESCO.
D35: ag.graúdo 3 | F35: 0 | G35: =IF(H9=0," ",$F35/($F$28+$F$29)) -> 0 | H35: =IF(H9=0," ",(($L35+($O35/(1+$M35)))/($L$28+$O$28+$L$29+$O$29))) -> 0 | I35: =IF(H9=0," ",$H35*$B$25) -> 0 | J35: ag.graúdo 3 | K35: =IF($J19=0," ",$J19) | L35: =IF(H9=0," ",$F35*($N$26/1000)) -> 0 | S35: A) Volume do recipíente = 1,57 litros
D36: água | F36: =IF(H9=0," ",H9) -> 205 | G36: =IF(H9=0," ",$F36/($F$28+$F$29)) -> 0.56164384 | H36: =IF(H9=0," ",($L36+$O36+($O30-($O30/(1+$M30)))+($O31-($O31/(1+$M31)))+($O32-($O32/(1+$M32)))+($O33-($O33/(1+$M33)))+($O34-($O34/(1+$M34)))+($O35-($O35/(1+$M35)))+($O36-($O36/(1+$M36))))/($L$28+$O$28+L29+O29)) -> 0.56164384 | I36: =IF(H9=0," ",$H36*$B$25) -> 0 | J36: água | L36: =IF(H9=0," ",$F36*($N$26/1000)) -> 5.125 | N36: =L36-(N31-L31)-(N30-L30) -> 5.125 | O36: 0 | S36: B) Peso do recipíente =
D37: aditivo 1(%) | F37: 1.65 | I37: =IF($H$9=0," ",$E37*($I$28+$I$29)) -> 0 | J37: aditivo 1 (litro) | K37: =IF($J20=0," ",$J20) -> TM828LF | L37: =IF(H9=0," ",$F37*($N$26/1000)*1000) -> 41.25 | S37: C) Peso do conjunto (conc + recip) =
D38: aditivo 2(%) | F38: 0 | I38: =IF($H$9=0," ",$E38*($I$28+$I$29)) -> 0 | J38: aditivo 2 (litro) | K38: =IF($J21=0," ",$J21) -> TF41N | L38: =IF(H9=0," ",$F38*($N$26/1000)*1000) -> 0 | S38: D) Peso do concreto = (C - B) =
D39: aditivo 3(%) | F39: 0 | I39: =IF($H$9=0," ",$E39*($I$28+$I$29)) -> 0 | J39: aditivo 3 (litro) | K39: =IF($J22=0," ",$J22) | L39: =IF(H9=0," ",$F39*($N$26/1000)*1000) -> 0 | S39: E) M. E.do conc. no estado fresco = (D / A) =
D40: adição 1(%) | F40: 0 | G40: =SUM(F28:F39) -> 2333.65 | I40: =IF($H$9=0," ",$E40*($I$28+$I$29)) -> 0 | J40: adição 1 | K40: =IF($J23=0," ",$J23) | L40: =IF(H9=0," ",$F40*($N$26/1000)) -> 0 | S40: S.T. INICIAL = 40mm
D41: adição 2 | I41: =IF($H$9=0," ",$E41*($I$28+$I$29)) -> 0 | J41: adição 2 | K41: =IF($J24=0," ",$J24) | L41: =IF(H9=0," ",$I41*($N$26/1000)) -> 0
D42: 5. Resultados obtidos do concreto fresco
...

Sheet Dosagem  0
E2: ESTUDO DE DOSAGEM DE CONCRETO
E5: ESTUDO/CLIENTE: | J5: DATA: | N5: DOSAGEM Nº:
E6: TRAÇO: | H6: APLICAÇÃO: | L6: CENTRAL:
E7: 1. Características do concreto / parâmetros de dosagem
E8: fck | F8: Sd | G8: Fc28d (Mpa) | H8: abatimento (mm) | I8: água (l/m3) | J8: consumo (kg/m3) | K8: a/c | L8: Targ.vol. (%) | M8: Tar (%) | N8: D Max | O8: Eci (Gpa | P8: Tipo de Lançamento
E9: 30 | F9: 5 | G9: =E9+(F9*1.65) -> 38.25 | H9: S160 | I9: 189 | J9: 321 | K9: =SUM(I9/J9) -> 0.58878505 | L9: 0.48 | M9: 0.03 | N9: 19.1 | O9: 28 | P9: Bombéavel
E11: 2. Materiais utilizados | J11: 3. Analise granulometrica % Retida | N11: 4. Analise granulometrica % Retida acumulado
E12: Material/ Fornecedor/Tipo/Classe | I12: Massa Especifica (g/cm³) | J12: Peneira Nª | K12: =E15 -> Ag.miúdo 1: | L12: =E16 -> Ag.miúdo 2: | M12: =E17 -> Ag.miúdo 3: | N12: =E18 -> Ag.graúdo 1: | O12: =E19 -> Ag.graúdo 2: | P12: =E20 -> Ag.graúdo 3:
E13: Cimento: | F13: CIMENTO CPII E 40 | I13: 3.05 | J13: 1" 1/8 | K13: 0 | L13: 0 | M13: 0 | N13: 0 | O13: 0 | P13: 0
E14: Aglom.2: | F14: SILCIA ATIVA | I14: 2.2 | J14: 1" | K14: 0 | L14: 0 | M14: 0 | N14: 0 | O14: 0 | P14: 0
E15: Ag.miúdo 1: | F15: AREIA NATURAL | I15: 2.63 | J15: 3/4" | K15: 0 | L15: 0 | M15: 0 | N15: 0 | O15: 3 | P15: 0
E16: Ag.miúdo 2: | F16: AREIA ARTIFICIAL | I16: 2.68 | J16: 1/2" | K16: 0 | L16: 0 | M16: 0 | N16: 0 | O16: 69 | P16: 0
E17: Ag.miúdo 3: | F17: - | I17: 1 | J17: 3/8" | K17: 0 | L17: 0 | M17: 0 | N17: 6 | O17: 91 | P17: 0
E18: Ag.graúdo 1: | F18: BRITA 0 | I18: 2.69 | J18: 1/4" | K18: 0.4 | L18: 0 | M18: 0 | N18: 63 | O18: 99 | P18: 0
E19: Ag.graúdo 2: | F19: BRITA 1 | I19: 2.69 | J19: 4 | K19: 0.7 | L19: 2.9 | M19: 0 | N19: 88 | O19: 100 | P19: 0
E20: Ag.graúdo 3: | F20: - | I20: 1 | J20: 8 | K20: 2 | L20: 16.6 | M20: 0 | N20: 95 | O20: 100 | P20: 0
E21: Aditivo 1: | F21: POLIFUNCIONAL | I21: 1.08 | J21: 16 | K21: 8.3 | L21: 14.1 | M21: 0 | N21: 96 | O21: 100 | P21: 0
E22: Aditivo 2: | F22: SUPERPLASTIFICANTE | I22: 1.1 | J22: 30 | K22: 23.8 | L22: 17.8 | M22: 0 | N22: 97 | O22: 100 | P22: 0
E23: Aditivo 3: | F23: INIBIDOR DE HIDRATAÇÃO | I23: 1 | J23: 50 | K23: 30.7 | L23: 23.4 | M23: 0 | N23: 98 | O23: 100 | P23: 0
E24: Adição 1: | F24: CRISTALIZANTE | I24: 3 | J24: 100 | K24: 24.5 | L24: 14.5 | M24: 0 | N24: 98 | O24: 100 | P24: 0
E25: Adição 2: | F25: MICROFIBRA | I25: 1 | J25: Fundo | K25: 9.5 | L25: 10.7 | M25: 0 | N25: 100 | O25: 100 | P25: 0
J26: Total | K26: 2.07 | L26: 2.72 | M26: =SUM(M13:M25) -> 0 | N26: 100 | O26: 100 | P26: 0
J27: M. Finura | K27: 2.1 | L27: 2.7 | N27: 5.77 | O27: 6.91
C28: =(1000-(M9*1000))/(((AX31+AX32)/(B32))+(AX33/I15)+(AX34/I16)+(AX35/I17)+(AX36/I18)+(AX37/I19)+(AX38/I20)+AX39) -> 320.99494 | E28: 5. Composição do traço
E29: DOSAGEM PARA 1 m3 - 1000 litros | I29: DOSAGEM PARA 1 BETONADA | L29: 25
B30: =(1-F32)*I13 -> 3.05 | E30: material | G30: Traço inicial | H30: Traço corr. | I30: Massa seca (kg) | J30: h(%) | K30: mat. corrig | L30: correção | R30: =SUM('Dosagem 0'!G31:G44)-G39 -> 2141.8506 | AW30: t.unitário | AX30: t.unit.cor. | AZ30: material
B31: =F32*I14 -> 0 | C31: =IF(J9<>0,J9,(I9/K9)) -> 321 | E31: =E13 -> Cimento: | G31: =IF(I9=0," ",(C31-G32)) -> 321 | H31: =IF(I9=0," ",C28-H32) -> 320.99494 | I31: =IF(I9=0," ",$G31*($L$29/1000)) -> 8.025 | J31: - | K31: - | R31: =('Dosagem 0'!G31+G32)/$R$30 -> 0.1498704 | S31: =G31 -> 321 | AW31: 1 | AX31: =IF(I9=0," ",($I31+$L31)/($I$31+$L$31)) -> 1 | AZ31: cimento | BA31: =IF($G13=0," ",$G13)
B32: =B30+B31 -> 3.05 | E32: =E14 -> Aglom.2: | F32: 0 | G32: =IF(I9=0," ",F32*C31) -> 0 | H32: =IF(I9=0," ",C28*F32) -> 0 | I32: =IF(I9=0," ",$G32*($L$29/1000)) -> 0 | J32: - | K32: - | R32: 0 | S32: =G32 -> 0 | AZ32: aglom.2 | BA32: =IF($G14=0," ",$G14)
B33: =$I15*$F33 -> 0.526 | E33: =E15 -> Ag.miúdo 1: | F33: 0.2 | G33: =IF(I9=0," ",(((1000-($M$9*1000)-$I$9)*$L$9)-($G$31/$I$13)-($G$32/$I$14))*$B$36*$F33) -> 143.98461 | H33: =IF(I9=0," ",$AX33*$C$28) -> 143.98234 | I33: =IF(I9=0," ",$G33*($L$29/1000)) -> 3.5996152 | J33: 0 | K33: =IF($J33=" "," ",$I33*(1+$J33)) -> 3.5996152 | R33: ='Dosagem 0'!G33/$R$30 -> 0.067224394 | S33: =G33 -> 143.98461 | AW33: =IF(I9=0," ",$G33/($G$31+$G$32)) -> 0.44855018 | AX33: =IF(I9=0," ",(($I33+($L33/(1+$J33)))/($I$31+$L$31+$I$32+$L$32))) -> 0.44855018 | AZ33: ag.miúdo 1 | BA33: =IF($G15=0," ",$G15)
B34: =$I16*$F34 -> 2.144 | E34: =E16 -> Ag.miúdo 2: | F34: 0.8 | G34: =IF(I9=0," ",(((1000-($M$9*1000)-$I$9)*$L$9)-($G$31/$I$13)-($G$32/$I$14))*$B$36*$F34) -> 575.93843 | H34: =IF(I9=0," ",$AX34*$C$28) -> 575.92935 | I34: =IF(I9=0," ",$G34*($L$29/1000)) -> 14.398461 | J34: 0 | K34: =IF($J34=" "," ",$I34*(1+$J34)) -> 14.398461 | R34: ='Dosagem 0'!G34/$R$30 -> 0.26889757 | S34: =G34 -> 575.93843 | AW34: =IF(I9=0," ",$G34/($G$31+$G$32)) -> 1.7942007 | AX34: =IF(I9=0," ",(($I34+($L34/(1+$J34)))/($I$31+$L$31+$I$32+$L$32))) -> 1.7942007 | AZ34: ag.miúdo 2 | BA34: =IF($G16=0," ",$G16)
B35: =$I17*$F35 -> 0 | E35: =E17 -> Ag.miúdo 3: | F35: 0 | G35: =IF(I9=0," ",(((1000-($M$9*1000)-$I$9)*$L$9)-($G$31/$I$13)-($G$32/$I$14))*$B$36*$F35) -> 0 | H35: =IF(I9=0," ",$AX35*$C$28) -> 0 | I35: =IF(I9=0," ",$G35*($L$29/1000)) -> 0 | R35: ='Dosagem 0'!G35/$R$30 -> 0 | S35: =G35 -> 0 | AW35: =IF(I9=0," ",$G35/($G$31+$G$32)) -> 0 | AX35: =IF(I9=0," ",(($I35+($L35/(1+$J35)))/($I$31+$L$31+$I$32+$L$32))) -> 0 | AZ35: ag.miúdo 3
B36: =B33+B34+B35 -> 2.67 | C36: =$I18*$F36 -> 0.807 | E36: =E18 -> Ag.graúdo 1: | F36: 0.3 | G36: =IF(I9=0," ",((((1000-($M$9*1000)-$G$39))-((1000-($M$9*1000)-$G$39)*$L$9)))*$C$39*$F36) -> 327.73884 | H36: =IF(I9=0," ",$AX36*$C$28) -> 327.73367 | I36: =IF(I9=0," ",$G36*($L$29/1000)) -> 8.193471 | R36: ='Dosagem 0'!G36/$R$30 -> 0.15301667 | S36: =G36 -> 327.73884 | AW36: =IF(I9=0," ",$G36/($G$31+$G$32)) -> 1.0209933 | AX36: =IF(I9=0," ",(($I36+($L36/(1+$J36)))/($I$31+$L$31+$I$32+$L$32))) -> 1.0209933 | AZ36: ag.graúdo 1 | BA36: =IF($G18=0," ",$G18)
C37: =$I19*$F37 -> 1.883 | E37: =E19 -> Ag.graúdo 2: | F37: 0.7 | G37: =IF(I9=0," ",((((1000-($M$9*1000)-$G$39))-((1000-($M$9*1000)-$G$39)*$L$9)))*$C$39*$F37) -> 764.72396 | H37: =IF(I9=0," ",$AX37*$C$28) -> 764.7119 | I37: =IF(I9=0," ",$G37*($L$29/1000)) -> 19.118099 | R37: ='Dosagem 0'!G37/$R$30 -> 0.35703889 | S37: =G37 -> 764.72396 | AW37: =IF(I9=0," ",$G37/($G$31+$G$32)) -> 2.3823176 | AX37: =IF(I9=0," ",(($I37+($L37/(1+$J37)))/($I$31+$L$31+$I$32+$L$32))) -> 2.3823176 | AZ37: ag.graúdo 2 | BA37: =IF($G19=0," ",$G19)
C38: =$I20*$F38 -> 0 | E38: =E20 -> Ag.graúdo 3: | F38: 0 | G38: =IF(I9=0," ",((((1000-($M$9*1000)-$G$39))-((1000-($M$9*1000)-$G$39)*$L$9)))*$C$39*$F38) -> 0 | H38: =IF(I9=0," ",$AX38*$C$28) -> 0 | I38: =IF(I9=0," ",$G38*($L$29/1000)) -> 0 | R38: ='Dosagem 0'!G38/$R$30 -> 0 | S38: =G38 -> 0 | AW38: =IF(I9=0," ",$G38/($G$31+$G$32)) -> 0 | AX38: =IF(I9=0," ",(($I38+($L38/(1+$J38)))/($I$31+$L$31+$I$32+$L$32))) -> 0 | AZ38: ag.graúdo 3 | BA38: =IF($G20=0," ",$G20)
C39: =C36+C37+C38 -> 2.69 | E39: água | G39: =IF(I9=0," ",I9) -> 189 | H39: =IF(I9=0," ",$AX39*$C$28) -> 188.99702 | I39: =IF(I9=0," ",$G39*($L$29/1000)) -> 4.725 | K39: =I39-(K34-I34)-(K33-I33) -> 4.725 | L39: 0 | R39: 0 | S39: =G39 -> 189 | AW39: =IF(I9=0," ",$G39/($G$31+$G$32)) -> 0.58878505 | AX39: =IF(I9=0," ",($I39+$L39+($L33-($L33/(1+$J33)))+($L34-($L34/(1+$J34)))+($L35-($L35/(1+$J35)))+($L36-($L36/(1+$J36)))+($L37-($L37/(1+$J37)))+($L38-($L38/(1+$J38)))+($L39-($L39/(1+$J39))))/($I$31+$L$31+I32+L32)) -> 0.58878505 | AZ39: água
E40: =E21 -> Aditivo 1: | F40: 0.0075 | G40: =IF(I9=0," ",$F40*($G$31+$G$32)) -> 2.4075 | H40: =IF($I$9=0," ",$F40*($H$31+$H$32)) -> 2.407462 | I40: =IF(I9=0," ",$G40*($L$29/1000)) -> 0.0601875 | R40: ='Dosagem 0'!G40/$R$30 -> 0.001124028 | S40: =G40 -> 2.4075 | AZ40: aditivo 1 (litro) | BA40: =IF($G21=0," ",$G21)
E41: =E22 -> Aditivo 2: | F41: 0.004 | G41: =IF(I9=0," ",$F41*($G$31+$G$32)) -> 1.284 | H41: =IF($I$9=0," ",$F41*($H$31+$H$32)) -> 1.2839797 | I41: =IF(I9=0," ",$G41*($L$29/1000)) -> 0.0321 | R41: ='Dosagem 0'!G41/$R$30 -> 0.00059948158 | S41: =G41 -> 1.284 | AZ41: aditivo 2 (litro) | BA41: =IF($G22=0," ",$G22)
E42: =E23 -> Aditivo 3: | F42: 0.003 | G42: =IF(I9=0," ",$F42*($G$31+$G$32)) -> 0.963 | H42: =IF($I$9=0," ",$F42*($H$31+$H$32)) -> 0.96298481 | I42: =IF(I9=0," ",$G42*($L$29/1000)) -> 0.024075 | R42: ='Dosagem 0'!G42/$R$30 -> 0.00044961119 | S42: =G42 -> 0.963 | AZ42: aditivo 3 (litro) | BA42: =IF($G23=0," ",$G23)
E43: =E24 -> Adição 1: | F43: 0.01 | G43: =IF(I9=0," ",$F43*($G$31+$G$32)) -> 3.21 | H43: =IF($I$9=0," ",$F43*($H$31+$H$32)) -> 3.2099494 | I43: =IF(I9=0," ",$G43*($L$29/1000)) -> 0.08025 | R43: ='Dosagem 0'!G43/$R$30 -> 0.001498704 | S43: =G43 -> 3.21 | AZ43: adição 1 | BA43: =IF($G24=0," ",$G24)
E44: =E25 -> Adição 2: | F44: 0.00187 | G44: =IF(I9=0," ",$F44*($G$31+$G$32)) -> 0.60027 | H44: =IF($I$9=0," ",$F44*($H$31+$H$32)) -> 0.60026053 | I44: =IF(I9=0," ",$H44*($L$29/1000)) -> 0.015006513 | R44: ='Dosagem 0'!G44/$R$30 -> 0.00028025764 | S44: =G44 -> 0.60027 | AZ44: adição 2 | BA44: =IF($G27=0," ",$G27)
...

Sheet Dosagem 
E2: ESTUDO DE DOSAGEM DE CONCRETO
E5: ESTUDO/CLIENTE: | J5: DATA: | K5: 45405 | N5: DOSAGEM Nº:
E6: TRAÇO: | H6: APLICAÇÃO: | L6: CENTRAL:
E7: 1. Características do concreto / parâmetros de dosagem
E8: fck | F8: Sd | G8: Fc28d (Mpa) | H8: abatimento (mm) | I8: água (l/m3) | J8: consumo (kg/m3) | K8: a/c | L8: Targ.vol. (%) | M8: Tar (%) | N8: D Max | O8: Eci (Gpa | P8: Tipo de Lançamento
E9: 30 | F9: 5 | G9: =E9+(F9*1.65) -> 38.25 | H9: S160 | I9: 189 | J9: 321 | K9: =SUM(I9/J9) -> 0.58878505 | L9: 0.48 | M9: 0.03 | N9: 19.1 | O9: 28 | P9: Bombéavel
E11: 2. Materiais utilizados | J11: 3. Analise grnulometrica % Retida | N11: 4. Analise grnulometrica % Retida acumulado
E12: Material/ Fornecedor/Tipo/Classe | I12: M. Especifica | J12: Peneira Nª | K12: =E15 -> Ag.miúdo 1: | L12: =E16 -> Ag.miúdo 2: | M12: =E17 -> Ag.miúdo 3: | N12: =E18 -> Ag.graúdo 1: | O12: =E19 -> Ag.graúdo 2: | P12: =E20 -> Ag.graúdo 3:
E13: Cimento: | F13: CIMENTO CPII E 40 | I13: 3.05 | J13: 1" 1/8 | K13: 0 | L13: 0 | M13: 0 | N13: 0 | O13: 0 | P13: 0
E14: Aglom.2: | F14: SILCIA ATIVA | I14: 2.2 | J14: 1" | K14: 0 | L14: 0 | M14: 0 | N14: 0 | O14: 0 | P14: 0
E15: Ag.miúdo 1: | F15: AREIA NATURAL | I15: 2.63 | J15: 3/4" | K15: 0 | L15: 0 | M15: 0 | N15: 0 | O15: 3 | P15: 0
E16: Ag.miúdo 2: | F16: AREIA ARTIFICIAL | I16: 2.68 | J16: 1/2" | K16: 0 | L16: 0 | M16: 0 | N16: 0 | O16: 69 | P16: 0
E17: Ag.miúdo 3: | F17: - | I17: 1 | J17: 3/8" | K17: 0 | L17: 0 | M17: 0 | N17: 6 | O17: 91 | P17: 0
E18: Ag.graúdo 1: | F18: BRITA 0 POLIMIX | I18: 2.69 | J18: 1/4" | K18: 0.4 | L18: 0 | M18: 0 | N18: 63 | O18: 99 | P18: 0
E19: Ag.graúdo 2: | F19: BRITA 1 POLIMIX | I19: 2.69 | J19: 4 | K19: 0.7 | L19: 2.9 | M19: 0 | N19: 88 | O19: 100 | P19: 0
E20: Ag.graúdo 3: | F20: - | I20: 1 | J20: 8 | K20: 2 | L20: 16.6 | M20: 0 | N20: 95 | O20: 100 | P20: 0
E21: Aditivo 1: | F21: POLIFUNCIONAL | I21: 1.08 | J21: 16 | K21: 8.3 | L21: 14.1 | M21: 0 | N21: 96 | O21: 100 | P21: 0
E22: Aditivo 2: | F22: SUPERPLASTIFICANTE | I22: 1.1 | J22: 30 | K22: 23.8 | L22: 17.8 | M22: 0 | N22: 97 | O22: 100 | P22: 0
E23: Aditivo 3: | F23: INIBIDOR DE HIDRATAÇÃO | I23: 1 | J23: 50 | K23: 30.7 | L23: 23.4 | M23: 0 | N23: 98 | O23: 100 | P23: 0
E24: Adição 1: | F24: CRISTALIZANTE | I24: 3 | J24: 100 | K24: 24.5 | L24: 14.5 | M24: 0 | N24: 98 | O24: 100 | P24: 0
E25: Adição 2: | F25: MICROFIBRA | I25: 1 | J25: Fundo | K25: 9.5 | L25: 10.7 | M25: 0 | N25: 100 | O25: 100 | P25: 0
J26: Total | K26: 2.07 | L26: 2.72 | M26: =SUM(M13:M25) -> 0 | N26: 100 | O26: 100 | P26: 0
J27: M. Finura | K27: 2.1 | L27: 2.7 | N27: 5.77 | O27: 6.91
C28: =(1000-(M9*1000))/(((AX31+AX32)/(B32))+(AX33/I15)+(AX34/I16)+(AX35/I17)+(AX36/I18)+(AX37/I19)+(AX38/I20)+AX39) -> 320.99494 | E28: 5. Composição do traço
E29: DOSAGEM PARA 1 m3 - 1000 litros | I29: DOSAGEM PARA 1 BETONADA | L29: 25
B30: =(1-F32)*I13 -> 3.05 | E30: material | G30: Traço inicial | H30: Traço corr. | I30: Massa seca (kg) | J30: h(%) | K30: mat. corrig | L30: correção | R30: =SUM('Dosagem '!G31:G44)-G39 -> 2141.8506 | AW30: t.unitário | AX30: t.unit.cor. | AZ30: material
B31: =F32*I14 -> 0 | C31: =IF(J9<>0,J9,(I9/K9)) -> 321 | E31: =E13 -> Cimento: | G31: =IF(I9=0," ",(C31-G32)) -> 321 | H31: =IF(I9=0," ",C28-H32) -> 320.99494 | I31: =IF(I9=0," ",$G31*($L$29/1000)) -> 8.025 | J31: - | K31: - | R31: =('Dosagem '!G31+G32)/$R$30 -> 0.1498704 | S31: =G31 -> 321 | AW31: 1 | AX31: =IF(I9=0," ",($I31+$L31)/($I$31+$L$31)) -> 1 | AZ31: cimento | BA31: =IF($G13=0," ",$G13)
B32: =B30+B31 -> 3.05 | E32: =E14 -> Aglom.2: | F32: 0 | G32: =IF(I9=0," ",F32*C31) -> 0 | H32: =IF(I9=0," ",C28*F32) -> 0 | I32: =IF(I9=0," ",$G32*($L$29/1000)) -> 0 | J32: - | K32: - | R32: 0 | S32: =G32 -> 0 | AZ32: aglom.2 | BA32: =IF($G14=0," ",$G14)
B33: =$I15*$F33 -> 0.526 | E33: =E15 -> Ag.miúdo 1: | F33: 0.2 | G33: =IF(I9=0," ",(((1000-($M$9*1000)-$I$9)*$L$9)-($G$31/$I$13)-($G$32/$I$14))*$B$36*$F33) -> 143.98461 | H33: =IF(I9=0," ",$AX33*$C$28) -> 143.98234 | I33: =IF(I9=0," ",$G33*($L$29/1000)) -> 3.5996152 | J33: 0 | K33: =IF($J33=" "," ",$I33*(1+$J33)) -> 3.5996152 | R33: ='Dosagem '!G33/$R$30 -> 0.067224394 | S33: =G33 -> 143.98461 | AW33: =IF(I9=0," ",$G33/($G$31+$G$32)) -> 0.44855018 | AX33: =IF(I9=0," ",(($I33+($L33/(1+$J33)))/($I$31+$L$31+$I$32+$L$32))) -> 0.44855018 | AZ33: ag.miúdo 1 | BA33: =IF($G15=0," ",$G15)
B34: =$I16*$F34 -> 2.144 | E34: =E16 -> Ag.miúdo 2: | F34: 0.8 | G34: =IF(I9=0," ",(((1000-($M$9*1000)-$I$9)*$L$9)-($G$31/$I$13)-($G$32/$I$14))*$B$36*$F34) -> 575.93843 | H34: =IF(I9=0," ",$AX34*$C$28) -> 575.92935 | I34: =IF(I9=0," ",$G34*($L$29/1000)) -> 14.398461 | J34: 0 | K34: =IF($J34=" "," ",$I34*(1+$J34)) -> 14.398461 | R34: ='Dosagem '!G34/$R$30 -> 0.26889757 | S34: =G34 -> 575.93843 | AW34: =IF(I9=0," ",$G34/($G$31+$G$32)) -> 1.7942007 | AX34: =IF(I9=0," ",(($I34+($L34/(1+$J34)))/($I$31+$L$31+$I$32+$L$32))) -> 1.7942007 | AZ34: ag.miúdo 2 | BA34: =IF($G16=0," ",$G16)
B35: =$I17*$F35 -> 0 | E35: =E17 -> Ag.miúdo 3: | F35: 0 | G35: =IF(I9=0," ",(((1000-($M$9*1000)-$I$9)*$L$9)-($G$31/$I$13)-($G$32/$I$14))*$B$36*$F35) -> 0 | H35: =IF(I9=0," ",$AX35*$C$28) -> 0 | I35: =IF(I9=0," ",$G35*($L$29/1000)) -> 0 | R35: ='Dosagem '!G35/$R$30 -> 0 | S35: =G35 -> 0 | AW35: =IF(I9=0," ",$G35/($G$31+$G$32)) -> 0 | AX35: =IF(I9=0," ",(($I35+($L35/(1+$J35)))/($I$31+$L$31+$I$32+$L$32))) -> 0 | AZ35: ag.miúdo 3
B36: =B33+B34+B35 -> 2.67 | C36: =$I18*$F36 -> 0.807 | E36: =E18 -> Ag.graúdo 1: | F36: 0.3 | G36: =IF(I9=0," ",((((1000-($M$9*1000)-$G$39))-((1000-($M$9*1000)-$G$39)*$L$9)))*$C$39*$F36) -> 327.73884 | H36: =IF(I9=0," ",$AX36*$C$28) -> 327.73367 | I36: =IF(I9=0," ",$G36*($L$29/1000)) -> 8.193471 | R36: ='Dosagem '!G36/$R$30 -> 0.15301667 | S36: =G36 -> 327.73884 | AW36: =IF(I9=0," ",$G36/($G$31+$G$32)) -> 1.0209933 | AX36: =IF(I9=0," ",(($I36+($L36/(1+$J36)))/($I$31+$L$31+$I$32+$L$32))) -> 1.0209933 | AZ36: ag.graúdo 1 | BA36: =IF($G18=0," ",$G18)
C37: =$I19*$F37 -> 1.883 | E37: =E19 -> Ag.graúdo 2: | F37: 0.7 | G37: =IF(I9=0," ",((((1000-($M$9*1000)-$G$39))-((1000-($M$9*1000)-$G$39)*$L$9)))*$C$39*$F37) -> 764.72396 | H37: =IF(I9=0," ",$AX37*$C$28) -> 764.7119 | I37: =IF(I9=0," ",$G37*($L$29/1000)) -> 19.118099 | R37: ='Dosagem '!G37/$R$30 -> 0.35703889 | S37: =G37 -> 764.72396 | AW37: =IF(I9=0," ",$G37/($G$31+$G$32)) -> 2.3823176 | AX37: =IF(I9=0," ",(($I37+($L37/(1+$J37)))/($I$31+$L$31+$I$32+$L$32))) -> 2.3823176 | AZ37: ag.graúdo 2 | BA37: =IF($G19=0," ",$G19)
C38: =$I20*$F38 -> 0 | E38: =E20 -> Ag.graúdo 3: | F38: 0 | G38: =IF(I9=0," ",((((1000-($M$9*1000)-$G$39))-((1000-($M$9*1000)-$G$39)*$L$9)))*$C$39*$F38) -> 0 | H38: =IF(I9=0," ",$AX38*$C$28) -> 0 | I38: =IF(I9=0," ",$G38*($L$29/1000)) -> 0 | R38: ='Dosagem '!G38/$R$30 -> 0 | S38: =G38 -> 0 | AW38: =IF(I9=0," ",$G38/($G$31+$G$32)) -> 0 | AX38: =IF(I9=0," ",(($I38+($L38/(1+$J38)))/($I$31+$L$31+$I$32+$L$32))) -> 0 | AZ38: ag.graúdo 3 | BA38: =IF($G20=0," ",$G20)
C39: =C36+C37+C38 -> 2.69 | E39: água | G39: =IF(I9=0," ",I9) -> 189 | H39: =IF(I9=0," ",$AX39*$C$28) -> 188.99702 | I39: =IF(I9=0," ",$G39*($L$29/1000)) -> 4.725 | K39: =I39-(K34-I34)-(K33-I33) -> 4.725 | L39: 0 | R39: 0 | S39: =G39 -> 189 | AW39: =IF(I9=0," ",$G39/($G$31+$G$32)) -> 0.58878505 | AX39: =IF(I9=0," ",($I39+$L39+($L33-($L33/(1+$J33)))+($L34-($L34/(1+$J34)))+($L35-($L35/(1+$J35)))+($L36-($L36/(1+$J36)))+($L37-($L37/(1+$J37)))+($L38-($L38/(1+$J38)))+($L39-($L39/(1+$J39))))/($I$31+$L$31+I32+L32)) -> 0.58878505 | AZ39: água
E40: =E21 -> Aditivo 1: | F40: 0.0075 | G40: =IF(I9=0," ",$F40*($G$31+$G$32)) -> 2.4075 | H40: =IF($I$9=0," ",$F40*($H$31+$H$32)) -> 2.407462 | I40: =IF(I9=0," ",$G40*($L$29/1000)) -> 0.0601875 | R40: ='Dosagem '!G40/$R$30 -> 0.001124028 | S40: =G40 -> 2.4075 | AZ40: aditivo 1 (litro) | BA40: =IF($G21=0," ",$G21)
E41: =E22 -> Aditivo 2: | F41: 0.004 | G41: =IF(I9=0," ",$F41*($G$31+$G$32)) -> 1.284 | H41: =IF($I$9=0," ",$F41*($H$31+$H$32)) -> 1.2839797 | I41: =IF(I9=0," ",$G41*($L$29/1000)) -> 0.0321 | R41: ='Dosagem '!G41/$R$30 -> 0.00059948158 | S41: =G41 -> 1.284 | AZ41: aditivo 2 (litro) | BA41: =IF($G22=0," ",$G22)
E42: =E23 -> Aditivo 3: | F42: 0.003 | G42: =IF(I9=0," ",$F42*($G$31+$G$32)) -> 0.963 | H42: =IF($I$9=0," ",$F42*($H$31+$H$32)) -> 0.96298481 | I42: =IF(I9=0," ",$G42*($L$29/1000)) -> 0.024075 | R42: ='Dosagem '!G42/$R$30 -> 0.00044961119 | S42: =G42 -> 0.963 | AZ42: aditivo 3 (litro) | BA42: =IF($G23=0," ",$G23)
E43: =E24 -> Adição 1: | F43: 0.01 | G43: =IF(I9=0," ",$F43*($G$31+$G$32)) -> 3.21 | H43: =IF($I$9=0," ",$F43*($H$31+$H$32)) -> 3.2099494 | I43: =IF(I9=0," ",$G43*($L$29/1000)) -> 0.08025 | R43: ='Dosagem '!G43/$R$30 -> 0.001498704 | S43: =G43 -> 3.21 | AZ43: adição 1 | BA43: =IF($G24=0," ",$G24)
E44: =E25 -> Adição 2: | F44: 0.00187 | G44: =IF(I9=0," ",$F44*($G$31+$G$32)) -> 0.60027 | H44: =IF($I$9=0," ",$F44*($H$31+$H$32)) -> 0.60026053 | I44: =IF(I9=0," ",$H44*($L$29/1000)) -> 0.015006513 | R44: ='Dosagem '!G44/$R$30 -> 0.00028025764 | S44: =G44 -> 0.60027 | AZ44: adição 2 | BA44: =IF($G27=0," ",$G27)
...

Sheet Curva de abrams
E3: =CONCATENATE("CURVAS DE ABRAMS - ",[3]Abrams!AG31) -> CURVAS DE ABRAMS - 28 dias
D5: A/C | E5: ÁGUA | F5: R 28
D6: 0.6 | E6: 195 | F6: 34 | H6: Coeficientes: y = A . x B
D7: 0.55 | E7: 195 | F7: 42.3 | I7: =[3]Abrams!AF7 -> TX 1
D8: 0.51 | E8: 195 | F8: 46.9 | H8: A= | I8: 15.209
D9: 0.45 | E9: 195 | F9: 55.3 | H9: B= | I9: -1.645
C23: FCK | D23: FC28 | E23: FATOR A/C | F23: ÁGUA | G23: CIMENTO
C24: 15 | D24: =C24+2*1.65 -> 18.3 | E24: =(D24/$I$8)^(1/$I$9) -> 0.89362386 | F24: =E6 -> 195 | G24: =ROUNDUP(F24/E24,0) -> 219
C25: 20 | D25: =C25+2.5*1.65 -> 24.125 | E25: =(D25/$I$8)^(1/$I$9) -> 0.75543405 | F25: =E6 -> 195 | G25: =ROUNDUP(F25/E25,0) -> 259
C26: 25 | D26: =C26+3.15*1.65 -> 30.1975 | E26: =(D26/$I$8)^(1/$I$9) -> 0.65905827 | F26: =E6 -> 195 | G26: =ROUNDUP(F26/E26,0) -> 296
C27: 30 | D27: =C27+4*1.65 -> 36.6 | E27: =(D27/$I$8)^(1/$I$9) -> 0.58635117 | F27: =E7 -> 195 | G27: =ROUNDUP(F27/E27,0) -> 333
C28: 35 | D28: =C28+4*1.65 -> 41.6 | E28: =(D28/$I$8)^(1/$I$9) -> 0.54243907 | F28: =E8 -> 195 | G28: =ROUNDUP(F28/E28,0) -> 360
C29: 40 | D29: =C29+5*1.65 -> 48.25 | E29: =(D29/$I$8)^(1/$I$9) -> 0.49567795 | F29: =E9 -> 195 | G29: =ROUNDUP(F29/E29,0) -> 394
L30: =J28/12 -> 0

Sheet Analise Granul.. - Ag Miúdo
G2: GRANULOMETRIA DA AREIA
B5: Abertura | D5: % retida | G5: % acumulada | J5: Areia mista | L5: Faixa ASTM | N5: Faixa Recomendada
B6: da peneira | D6: ='Dosagem '!E33 -> Ag.miúdo 1: | E6: ='Dosagem '!E34 -> Ag.miúdo 2: | F6: ='Dosagem '!E35 -> Ag.miúdo 3: | G6: Fina | H6: Média | I6: Grossa | J6: Retida | K6: Acumul | L6: % acumulada | N6: % retida
B7: No. | C7: ( mm ) | D7: ='Dosagem '!F33 -> 0.2 | E7: ='Dosagem '!F34 -> 0.8 | F7: ='Dosagem '!F35 -> 0 | J7: ( % ) | K7: ( % ) | L7: Super. | M7: Infer. | N7: Super. | O7: Ideal | P7: Infer.
B8: ='Dosagem '!J18 -> 1/4" | C8: 6.3 | D8: ='Dosagem '!K18 -> 0.4 | E8: ='Dosagem '!L18 -> 0 | F8: ='Dosagem '!M18 -> 0 | G8: =D8 -> 0.4 | H8: =E8 -> 0 | I8: =F8 -> 0 | J8: =D$7*D8+E$7*E8+F$7*F8 -> 0.08 | K8: =J8 -> 0.08 | L8: 0 | M8: 0 | N8: 0 | O8: 0 | P8: 0
B9: ='Dosagem '!J19 -> 4 | C9: 4.8 | D9: ='Dosagem '!K19 -> 0.7 | E9: ='Dosagem '!L19 -> 2.9 | F9: ='Dosagem '!M19 -> 0 | G9: =G8+D9 -> 1.1 | H9: =H8+E9 -> 2.9 | I9: =I8+F9 -> 0 | J9: =D$7*D9+E$7*E9+F$7*F9 -> 2.46 | K9: =K8+J9 -> 2.54 | L9: 0 | M9: 10 | N9: 5 | O9: 2 | P9: 0
B10: ='Dosagem '!J20 -> 8 | C10: 2.4 | D10: ='Dosagem '!K20 -> 2 | E10: ='Dosagem '!L20 -> 16.6 | F10: ='Dosagem '!M20 -> 0 | G10: =G9+D10 -> 3.1 | H10: =H9+E10 -> 19.5 | I10: =I9+F10 -> 0 | J10: =D$7*D10+E$7*E10+F$7*F10 -> 13.68 | K10: =K9+J10 -> 16.22 | L10: 0 | M10: 20 | N10: 22 | O10: 12 | P10: 3
B11: ='Dosagem '!J21 -> 16 | C11: 1.2 | D11: ='Dosagem '!K21 -> 8.3 | E11: ='Dosagem '!L21 -> 14.1 | F11: ='Dosagem '!M21 -> 0 | G11: =G10+D11 -> 11.4 | H11: =H10+E11 -> 33.6 | I11: =I10+F11 -> 0 | J11: =D$7*D11+E$7*E11+F$7*F11 -> 12.94 | K11: =K10+J11 -> 29.16 | L11: 10 | M11: 50 | N11: 32 | O11: 21 | P11: 12
B12: ='Dosagem '!J22 -> 30 | C12: 0.6 | D12: ='Dosagem '!K22 -> 23.8 | E12: ='Dosagem '!L22 -> 17.8 | F12: ='Dosagem '!M22 -> 0 | G12: =G11+D12 -> 35.2 | H12: =H11+E12 -> 51.4 | I12: =I11+F12 -> 0 | J12: =D$7*D12+E$7*E12+F$7*F12 -> 19 | K12: =K11+J12 -> 48.16 | L12: 35 | M12: 75 | N12: 33 | O12: 22 | P12: 13
B13: ='Dosagem '!J23 -> 50 | C13: 0.3 | D13: ='Dosagem '!K23 -> 30.7 | E13: ='Dosagem '!L23 -> 23.4 | F13: ='Dosagem '!M23 -> 0 | G13: =G12+D13 -> 65.9 | H13: =H12+E13 -> 74.8 | I13: =I12+F13 -> 0 | J13: =D$7*D13+E$7*E13+F$7*F13 -> 24.86 | K13: =K12+J13 -> 73.02 | L13: 65 | M13: 90 | N13: 32 | O13: 21 | P13: 12
B14: ='Dosagem '!J24 -> 100 | C14: 0.15 | D14: ='Dosagem '!K24 -> 24.5 | E14: ='Dosagem '!L24 -> 14.5 | F14: ='Dosagem '!M24 -> 0 | G14: =G13+D14 -> 90.4 | H14: =H13+E14 -> 89.3 | I14: =I13+F14 -> 0 | J14: =D$7*D14+E$7*E14+F$7*F14 -> 16.5 | K14: =K13+J14 -> 89.52 | L14: 90 | M14: 98 | N14: 24 | O14: 18 | P14: 9
B15: ='Dosagem '!J25 -> Fundo | C15: 0 | D15: ='Dosagem '!K25 -> 9.5 | E15: ='Dosagem '!L25 -> 10.7 | F15: ='Dosagem '!M25 -> 0 | G15: =G14+D15 -> 99.9 | H15: =H14+E15 -> 100 | I15: =I14+F15 -> 0 | J15: =D$7*D15+E$7*E15+F$7*F15 -> 10.46 | K15: =K14+J15 -> 99.98 | L15: 100 | M15: 100 | N15: 10 | O15: 4 | P15: 2
B16: Total | D16: =SUM(D8:D15) -> 99.9 | E16: ='Dosagem '!L26 -> 2.72 | F16: ='Dosagem '!M26 -> 0 | J16: =SUM(J8:J15) -> 99.98 | O16: =SUM(O8:O15) -> 100
B17: M. finura | G17: =#REF!/100 -> #REF! | K17: =#REF!/100 -> #REF! | L17: =#REF!/100 -> #REF! | M17: =#REF!/100 -> #REF!

Sheet Pedra 0+1
B2: GRANULOMETRIA COMBINADA B0 IBRATA + B1 IBRATA | Q2: 0 | R2: 100 | S2: 100
F3: Faixa : | H3: =INDIRECT(C69) -> ( 19 a 4,8 )
B5: Tamanho de | D5: Aberturas das peneiras
B6: de | C6: % de mistuta graúdo | D6: 1 1/2" | E6: 1 1/8" | F6: 1" | G6: 3/4" | H6: 1/2" | I6: "3/8 | J6: 1/4" | K6: 4 | L6: 8 | M6: Fundo
B7: agregado | C7: Acumulado | D7: 38 mm | E7: 32 mm | F7: 25 mm | G7: 19 mm | H7: 12,7 mm | I7: 9,5 mm | J7: 6,3 mm | K7: 4,8 mm | L7: 2,4 mm | M7: 0,0 mm
B8: Pedra 0 | C8: ='Dosagem '!F36 -> 0.3 | D8: 0 | E8: 0 | F8: 0 | G8: ='Dosagem '!N15 -> 0 | H8: ='Dosagem '!N16 -> 0 | I8: ='Dosagem '!N17 -> 6 | J8: ='Dosagem '!N18 -> 63 | K8: ='Dosagem '!N19 -> 88 | L8: ='Dosagem '!N20 -> 95 | M8: ='Dosagem '!N25 -> 100
B9: Pedra 1 | C9: ='Dosagem '!F37 -> 0.7 | D9: 0 | E9: 0 | F9: ='Dosagem '!O14 -> 0 | G9: ='Dosagem '!O15 -> 3 | H9: ='Dosagem '!O16 -> 69 | I9: ='Dosagem '!O17 -> 91 | J9: ='Dosagem '!O18 -> 99 | K9: ='Dosagem '!O19 -> 100 | L9: ='Dosagem '!O20 -> 100 | M9: ='Dosagem '!O25 -> 100
B10: Pedra 2 | C10: ='Dosagem '!F38 -> 0 | D10: 0 | E10: 0 | M10: 100
B11: Mista | D11: =D8*$C8+D9*$C9+D10*$C10 -> 0 | E11: =E8*$C8+E9*$C9+E10*$C10 -> 0 | F11: =F8*$C8+F9*$C9+F10*$C10 -> 0 | G11: =G8*$C8+G9*$C9+G10*$C10 -> 2.1 | H11: =H8*$C8+H9*$C9+H10*$C10 -> 48.3 | I11: =I8*$C8+I9*$C9+I10*$C10 -> 65.5 | J11: =J8*$C8+J9*$C9+J10*$C10 -> 88.2 | K11: =K8*$C8+K9*$C9+K10*$C10 -> 96.4 | L11: =L8*$C8+L9*$C9+L10*$C10 -> 98.5 | M11: 100
B12: Faixa superior | D12: =INDIRECT(D68) -> 0 | E12: =INDIRECT(E68) -> 0 | F12: =INDIRECT(F68) -> 0 | G12: =INDIRECT(G68) -> 0 | H12: =INDIRECT(H68) -> 0 | I12: =INDIRECT(I68) -> 20 | J12: =INDIRECT(J68) -> 45 | K12: =INDIRECT(K68) -> 72.855713 | ... M12: =INDIRECT(M68) -> 95
B13: Faixa inferior | D13: =INDIRECT(D69) -> 0 | E13: =INDIRECT(E69) -> 0 | F13: =INDIRECT(F69) -> 0 | G13: =INDIRECT(G69) -> 0 | H13: =INDIRECT(H69) -> 10 | I13: =INDIRECT(I69) -> 45 | J13: =INDIRECT(J69) -> 80 | K13: =INDIRECT(K69) -> 92.380317 | ... M13: =INDIRECT(M69) -> 100
B35: TABELA 2 - Limites de granulometricos de agregados graudos
B37: Graduação | D37: 1 1/2" | E37: 11/8" | F37: 1" | G37: 3/4" | H37: 1/2" | I37: "3/8 | J37: 1/4" | K37: 4 | L37: 8 | M37: Fundo
B38: [ JIS ] | D38: 38 mm | E38: 32 mm | F38: 25 mm | G38: 19 mm | H38: 12,7 mm | I38: 9,5 mm | J38: 6,3 mm | K38: 4,8 mm | L38: 2,4 mm | M38: 0,0 mm
H39: 0 | I39: 0 | J39: =(LOG(9.8)-LOG(6.3))/(LOG(9.8)-LOG(4.8))*(K39-I39)+I39 -> 37.140951 | K39: 60 | L39: 90 | M39: 100
B40: ( 9,5 a 4,8 ) | H40: 0 | I40: 15 | J40: =(LOG(9.8)-LOG(6.3))/(LOG(9.8)-LOG(4.8))*(K40-I40)+I40 -> 67.616347 | K40: 100 | L40: 100 | M40: 100
G41: 0 | H41: 0 | I41: 30 | J41: =(LOG(9.8)-LOG(6.3))/(LOG(9.8)-LOG(4.8))*(K41-I41)+I41 -> 64.045871 | K41: 85 | L41: 95 | M41: 100
B42: ( 13 a 4,8 ) | G42: 0 | H42: 10 | I42: 60 | J42: =(LOG(9.8)-LOG(6.3))/(LOG(9.8)-LOG(4.8))*(K42-I42)+I42 -> 84.760634 | K42: 100 | L42: 100 | M42: 100
F43: 0 | G43: 0 | H43: 20 | I43: 45 | J43: =(LOG(9.8)-LOG(6.3))/(LOG(9.8)-LOG(4.8))*(K43-I43)+I43 -> 72.855713 | K43: 90 | L43: 95 | M43: 100
B44: ( 19 a 4,8 ) | F44: 0 | G44: 10 | H44: 45 | I44: 80 | J44: =(LOG(9.8)-LOG(6.3))/(LOG(9.8)-LOG(4.8))*(K44-I44)+I44 -> 92.380317 | K44: 100 | L44: 100 | M44: 100
E45: 0 | F45: 0 | G45: 10 | H45: 30 | I45: 50 | J45: =(LOG(9.8)-LOG(6.3))/(LOG(9.8)-LOG(4.8))*(K45-I45)+I45 -> 74.760634 | K45: 90 | L45: 95 | M45: 100
B46: ( 25 a 4,8 ) | E46: 0 | F46: 5 | G46: 40 | H46: 70 | I46: 80 | J46: =(LOG(9.8)-LOG(6.3))/(LOG(9.8)-LOG(4.8))*(K46-I46)+I46 -> 92.380317 | K46: 100 | L46: 100 | M46: 100
D47: 0 | E47: 0 | F47: =(LOG(32)-LOG(25))/(LOG(32)-LOG(19))*(G47-E47)+E47 -> 11.838746 | G47: 25 | H47: =(LOG(19)-LOG(12.7))/(LOG(19)-LOG(9.5))*(I47-G47)+G47 -> 48.246837 | I47: 65 | J47: =(LOG(9.8)-LOG(6.3))/(LOG(9.8)-LOG(4.8))*(K47-I47)+I47 -> 83.570475 | K47: 95 | L47: 100 | M47: 100
B48: ( 32 a 4,8 ) | D48: 0 | E48: 5 | F48: =(LOG(32)-LOG(25))/(LOG(32)-LOG(19))*(G48-E48)+E48 -> 31.045242 | G48: 60 | H48: =(LOG(19)-LOG(12.7))/(LOG(19)-LOG(9.5))*(I48-G48)+G48 -> 77.435128 | I48: 90 | J48: =(LOG(9.8)-LOG(6.3))/(LOG(9.8)-LOG(4.8))*(K48-I48)+I48 -> 96.190158 | K48: 100 | L48: 100 | M48: 100
D49: 0 | E49: =(LOG(38)-LOG(32))/(LOG(38)-LOG(19))*(G49-D49)+D49 -> 7.4378254 | F49: =(LOG(38)-LOG(25))/(LOG(38)-LOG(19))*(G49-D49)+D49 -> 18.12214 | G49: 30 | H49: =(LOG(19)-LOG(12.7))/(LOG(19)-LOG(9.5))*(I49-G49)+G49 -> 53.246837 | I49: 70 | J49: =(LOG(9.8)-LOG(6.3))/(LOG(9.8)-LOG(4.8))*(K49-I49)+I49 -> 85.475396 | K49: 95 | L49: 100 | M49: 100
B50: ( 38 a 4,8 ) | D50: 5 | E50: =(LOG(38)-LOG(32))/(LOG(38)-LOG(19))*(G50-D50)+D50 -> 19.875651 | F50: =(LOG(38)-LOG(25))/(LOG(38)-LOG(19))*(G50-D50)+D50 -> 41.244279 | G50: 65 | H50: =(LOG(19)-LOG(12.7))/(LOG(19)-LOG(9.5))*(I50-G50)+G50 -> 79.529273 | I50: 90 | J50: =(LOG(9.8)-LOG(6.3))/(LOG(9.8)-LOG(4.8))*(K50-I50)+I50 -> 96.190158 | K50: 100 | L50: 100 | M50: 100
D51: 0 | E51: =(LOG(38)-LOG(32))/(LOG(38)-LOG(19))*(F51-D51)+D51 -> 11.156738 | F51: 45 | G51: 85 | H51: =(LOG(19)-LOG(12.7))/(LOG(19)-LOG(9.5))*(I51-G51)+G51 -> 90.811709 | I51: 95 | J51: =(LOG(9.8)-LOG(6.3))/(LOG(9.8)-LOG(4.8))*(K51-I51)+I51 -> 98.095079 | K51: 100 | L51: 100 | M51: 100
B52: ( 38 a 19 ) | D52: 10 | E52: =(LOG(38)-LOG(32))/(LOG(38)-LOG(19))*(F52-D52)+D52 -> 27.354926 | F52: 80 | G52: 100 | H52: =(LOG(19)-LOG(12.7))/(LOG(19)-LOG(9.5))*(I52-G52)+G52 -> 100 | I52: 100 | J52: =(LOG(9.8)-LOG(6.3))/(LOG(9.8)-LOG(4.8))*(K52-I52)+I52 -> 100 | K52: 100 | L52: 100 | M52: 100
C53: Obs. : | D53: 17,4 39,9 ----- 90,8 | F53: são interporados
F66: Atenção !! Não mexxer quadro abaixo !!
B68: ='[2]Pedra 0+1 riomix'!C1*2+39 -> 43 | D68: =ADDRESS($B68,3,4,TRUE) -> C43 | E68: =ADDRESS($B68,4,4,TRUE) -> D43 | F68: =ADDRESS($B68,5,4,TRUE) -> E43 | G68: =ADDRESS($B68,6,4,TRUE) -> F43 | H68: =ADDRESS($B68,7,4,TRUE) -> G43 | I68: =ADDRESS($B68,8,4,TRUE) -> H43 | J68: =ADDRESS($B68,9,4,TRUE) -> I43 | K68: =ADDRESS($B68,10,4,TRUE) -> J43 | L68: =ADDRESS($B68,11,4,TRUE) -> K43 | M68: =ADDRESS($B68,12,4,TRUE) -> L43
B69: =B68+1 -> 44 | C69: =ADDRESS($B69,2,4,TRUE) -> B44 | D69: =ADDRESS($B69,3,4,TRUE) -> C44 | E69: =ADDRESS($B69,4,4,TRUE) -> D44 | F69: =ADDRESS($B69,5,4,TRUE) -> E44 | G69: =ADDRESS($B69,6,4,TRUE) -> F44 | H69: =ADDRESS($B69,7,4,TRUE) -> G44 | I69: =ADDRESS($B69,8,4,TRUE) -> H44 | J69: =ADDRESS($B69,9,4,TRUE) -> I44 | K69: =ADDRESS($B69,10,4,TRUE) -> J44 | L69: =ADDRESS($B69,11,4,TRUE) -> K44 | M69: =ADDRESS($B69,12,4,TRUE) -> L44

Sheet Analise Combinação de materiais
L2: (%) correspondente | Q2: =SUM(I4:O4) -> 0.99604792
C3: Peneiras | D3: ='Analise Granul.. - Ag Miúdo'!$J$5 -> Areia mista | E3: ='Pedra 0+1'!$C$6 -> % de mistuta graúdo | F3: cimento | I3: ='Dosagem '!$E$31 -> Cimento: | J3: ='Analise Granul.. - Ag Miúdo'!$D$6 -> Ag.miúdo 1: | K3: ='Analise Granul.. - Ag Miúdo'!$E$6 -> Ag.miúdo 2: | L3: ='Analise Granul.. - Ag Miúdo'!$F$6 -> Ag.miúdo 3: | M3: ='Dosagem '!$E$36 -> Ag.graúdo 1: | N3: ='Dosagem '!$E$37 -> Ag.graúdo 2: | O3: ='Dosagem '!$E$38 -> Ag.graúdo 3: | Q3: Curva retida acumulada - Concreto
C4: mm | D4: Acumulado | E4: ='Pedra 0+1'!$C$7 -> Acumulado | I4: ='Dosagem '!$R$31 -> 0.1498704 | J4: ='Dosagem '!$R$33 -> 0.067224394 | K4: ='Dosagem '!$R$34 -> 0.26889757 | L4: ='Dosagem '!$R$35 -> 0 | M4: ='Dosagem '!$R$36 -> 0.15301667 | N4: ='Dosagem '!$R$37 -> 0.35703889 | O4: ='Dosagem '!$R$38 -> 0 | Q4: %
D5: ='Analise Granul.. - Ag Miúdo'!$J$7 -> ( % ) | E5: (%) | F5: (%)
C6: 76 | S6: =100-Q6 -> 100
C7: 64 | Q7: =SUM(I7:O7) -> 0 | S7: =100-Q7 -> 100
C8: 50 | E8: 0 | M8: =$M$4*E8 -> 0 | N8: =$N$4*E8 -> 0 | O8: =$O$4*E8 -> 0 | Q8: =SUM(I8:O8) -> 0 | S8: =100-Q8 -> 100
C9: 38 | E9: ='Pedra 0+1'!$D$11 -> 0 | M9: =$M$4*E9 -> 0 | N9: =$N$4*E9 -> 0 | O9: =$O$4*E9 -> 0 | Q9: =SUM(I9:O9) -> 0 | S9: =100-Q9 -> 100
C10: 32 | E10: ='Pedra 0+1'!$E$11 -> 0 | M10: =$M$4*E10 -> 0 | N10: =$N$4*E10 -> 0 | O10: =$O$4*E10 -> 0 | Q10: =SUM(I10:O10) -> 0 | S10: =100-Q10 -> 100
C11: 25 | E11: ='Pedra 0+1'!$F$11 -> 0 | M11: =$M$4*E11 -> 0 | N11: =$N$4*E11 -> 0 | O11: =$O$4*E11 -> 0 | Q11: =SUM(I11:O11) -> 0 | S11: =100-Q11 -> 100
C12: 19 | E12: ='Pedra 0+1'!$G$11 -> 2.1 | M12: =$M$4*E12 -> 0.321335 | N12: =$N$4*E12 -> 0.74978166 | O12: =$O$4*E12 -> 0 | Q12: =SUM(I12:O12) -> 1.0711167 | S12: =100-Q12 -> 98.928883
C13: 12.5 | E13: ='Pedra 0+1'!$H$11 -> 48.3 | M13: =$M$4*E13 -> 7.390705 | N13: =$N$4*E13 -> 17.244978 | O13: =$O$4*E13 -> 0 | Q13: =SUM(I13:O13) -> 24.635683 | S13: =100-Q13 -> 75.364317
C14: 9.5 | E14: ='Pedra 0+1'!$I$11 -> 65.5 | M14: =$M$4*E14 -> 10.022592 | N14: =$N$4*E14 -> 23.386047 | O14: =$O$4*E14 -> 0 | Q14: =SUM(I14:O14) -> 33.408639 | S14: =100-Q14 -> 66.591361
C15: 6.3 | E15: ='Pedra 0+1'!$J$11 -> 88.2 | M15: =$M$4*E15 -> 13.49607 | N15: =$N$4*E15 -> 31.49083 | O15: =$O$4*E15 -> 0 | Q15: =SUM(I15:O15) -> 44.9869 | S15: =100-Q15 -> 55.0131
C16: 4.8 | D16: ='Analise Granul.. - Ag Miúdo'!$K$9 -> 2.54 | E16: ='Pedra 0+1'!$K$11 -> 96.4 | J16: =$J$4*D16 -> 0.17074996 | K16: =$K$4*D16 -> 0.68299984 | L16: =$L$4*D16 -> 0 | M16: =$M$4*E16 -> 14.750807 | N16: =$N$4*E16 -> 34.418549 | O16: =$O$4*E16 -> 0 | Q16: =SUM(I16:O16) -> 50.023105 | S16: =100-Q16 -> 49.976895
C17: 2.4 | D17: ='Analise Granul.. - Ag Miúdo'!$K$10 -> 16.22 | E17: ='Pedra 0+1'!$L$11 -> 98.5 | J17: =$J$4*D17 -> 1.0903797 | K17: =$K$4*D17 -> 4.3615187 | L17: =$L$4*D17 -> 0 | M17: =$M$4*E17 -> 15.072142 | N17: =$N$4*E17 -> 35.16833 | O17: =$O$4*E17 -> 0 | Q17: =SUM(I17:O17) -> 55.69237 | S17: =100-Q17 -> 44.30763
C18: 1.2 | D18: ='Analise Granul.. - Ag Miúdo'!$K$11 -> 29.16 | E18: 100 | J18: =$J$4*D18 -> 1.9602633 | K18: =$K$4*D18 -> 7.8410533 | L18: =$L$4*D18 -> 0 | M18: =$M$4*E18 -> 15.301667 | N18: =$N$4*E18 -> 35.703889 | O18: =$O$4*E18 -> 0 | Q18: =SUM(I18:O18) -> 60.806872 | S18: =100-Q18 -> 39.193128
C19: 0.6 | D19: ='Analise Granul.. - Ag Miúdo'!$K$12 -> 48.16 | E19: 100 | J19: =$J$4*D19 -> 3.2375268 | K19: =$K$4*D19 -> 12.950107 | L19: =$L$4*D19 -> 0 | M19: =$M$4*E19 -> 15.301667 | N19: =$N$4*E19 -> 35.703889 | O19: =$O$4*E19 -> 0 | Q19: =SUM(I19:O19) -> 67.193189 | S19: =100-Q19 -> 32.806811
C20: 0.3 | D20: ='Analise Granul.. - Ag Miúdo'!$K$13 -> 73.02 | E20: 100 | J20: =$J$4*D20 -> 4.9087252 | K20: =$K$4*D20 -> 19.634901 | L20: =$L$4*D20 -> 0 | M20: =$M$4*E20 -> 15.301667 | N20: =$N$4*E20 -> 35.703889 | O20: =$O$4*E20 -> 0 | Q20: =SUM(I20:O20) -> 75.549181 | S20: =100-Q20 -> 24.450819
C21: 0.15 | D21: ='Analise Granul.. - Ag Miúdo'!$K$14 -> 89.52 | E21: 100 | J21: =$J$4*D21 -> 6.0179277 | K21: =$K$4*D21 -> 24.071711 | L21: =$L$4*D21 -> 0 | M21: =$M$4*E21 -> 15.301667 | N21: =$N$4*E21 -> 35.703889 | O21: =$O$4*E21 -> 0 | Q21: =SUM(I21:O21) -> 81.095194 | S21: =100-Q21 -> 18.904806
C22: 0.075 | D22: 100 | E22: 100 | F22: 0.55 | I22: =I4*F22 -> 0.082428718 | J22: =$J$4*D22 -> 6.7224394 | K22: =$K$4*D22 -> 26.889757 | L22: =$L$4*D22 -> 0 | M22: =$M$4*E22 -> 15.301667 | N22: =$N$4*E22 -> 35.703889 | O22: =$O$4*E22 -> 0 | Q22: =SUM(I22:O22) -> 84.700181 | S22: =100-Q22 -> 15.299819
C23: FUNDO | D23: ='Analise Granul.. - Ag Miúdo'!$K$15 -> 99.98 | E23: ='Pedra 0+1'!$M$11 -> 100 | F23: 100 | J23: =$J$4*D23 -> 6.7210949 | K23: =$K$4*D23 -> 26.884379 | L23: =$L$4*D23 -> 0 | M23: =$M$4*E23 -> 15.301667 | N23: =$N$4*E23 -> 35.703889 | O23: =$O$4*E23 -> 0 | Q23: =SUM(I23:O23) -> 84.61103
C24: TOTAL

Sheet Dosagem - calculo
E2: TRAÇO EXPERIMENTAL DE LABORATÓRIO
AI3: MATERIAL | AK3: MASSA ESPECIFICA (g/cm³)
E4: 1. Identificação | AI4: Areia Nat | AK4: 2.63
E5: ESTUDO/CLIENTE: | J5: DATA: | K5: 44857 | N5: DOSAGEM Nº: | AI5: Areia art | AK5: 2.69
E6: TRAÇO: | H6: APLICAÇÃO: | L6: CENTRAL: | T6: a) Dados de entrada | AI6: Brita 0 | AK6: 2.7
E7: 2. Características do concreto / parâmetros de dosagem | AI7: Brita 1 | AK7: 2.7
E8: fck | F8: Sd | G8: Fc28d (Mpa) | H8: abatimento (mm) | I8: água (l/m3) | J8: consumo (kg/m3) | K8: a/c | L8: Targ.vol. (%) | M8: Tar (%) | N8: D Max | O8: Eci (Gpa | P8: Tipo de Lançamento | T8: fck | U8: Sd | V8: Fc28d (Mpa) | W8: abatimento (mm) | X8: água (l/m3) | Y8: consumo (kg/m3) | Z8: a/c | AA8: T arg.vol. (%) | AB8: Brita 0/1 | AC8: areia nat/art | AD8: Tar (%) | AE8: D Max | AF8: Tipo de Lançamento | AI8: CIMENTO | AK8: 3.08
E9: 35 | F9: 4 | G9: 35 | H9: 100 | I9: 190 | J9: 380 | K9: =SUM(I9/J9) -> 0.5 | L9: 0.49 | M9: 0.025 | N9: 19.1 | O9: 28 | P9: Bombéavel | T9: 35 | U9: 4 | V9: 35 | W9: 100 | X9: 190 | Y9: 380 | Z9: =SUM(X9/Y9) -> 0.5 | AA9: 0.49 | AB9: 30/70% | AC9: 40/60% | AD9: 0.025 | AE9: 19.1 | AF9: Bombéavel
E10: 3. Materiais utilizados
E11: material | G11: descrição | I11: Fornecedor | K11: tipo/classe | L11: M. Finura | M11: M. Especidica
E12: cimento | G12: CIMENTO | I12: CAUÊ | K12: CPII E 40 | L12: 4.35 | M12: 3.08 | T12: b) Qtidade de cimento = água / a/c
E13: aglom.2 | M13: 1
E14: 3.3 ag.miúdo 1 | G14: AREIA DE QUARTZO | I14: C131 BARÃO | K14: AQFINA | M14: 2.63 | T14: Ex. 200/0,5 = | V14: =X9/Z9 -> 380 | W14: kg/m3
E15: ag.miúdo 2 | G15: AREIA DE QUARTZO | I15: ITAPORANGA | K15: AQGROSSA | M15: 2.69
E16: ag.miúdo 3 | M16: 1 | T16: c) Quantidade de areia:
E17: ag.graúdo 1 | G17: Pedrisco | I17: GALVANI | K17: Brita 0 | M17: 2.7
E18: ag.graúdo 2 | G18: Brita 1 | I18: GALVANI | K18: Brita 1 | M18: 2.7 | T18: Qtde de areia nat = ((v°- %ar-água)*%arg)-(qtde cimento/myc)*My agregados miúdos proporcional * %areia nat | AH18: My agregados miúdos proporcional
E19: ag.graúdo 3 | M19: 1 | AH19: proporção areia nat e art: 40/60 = (40%*2,63 + 60%2,69) = | AL19: =2.63*40%+2.69*60% -> 2.666
E20: aditivo 1 | G20: Tec Mult 828LF | I20: Rheoset | K20: TM828LF | M20: 1.18 | T20: ex. | U20: ((1000-25-200)*49%))-(400/3,08)*2,67*40%)) = | Z20: =((((1000-25-X9)*AA9)-(Y9/3.08))*AL19*40%) -> 278.62193 | AA20: kg/m3
E21: aditivo 2 | G21: Tec Flow 41N | I21: Rheoset | K21: TF41N | M21: 1.1
E22: aditivo 3 | M22: 1 | T22: Qtde de areia art = ((v°- %ar-água)*%arg)-(qtde cimento/myc)*My agregados miúdos proporcional * %areia art
E23: adição 1 | M23: 1
E24: adição 2 | M24: 1 | T24: ex. | U24: ((1000-25-200)*49%))-(400/3,08)*2,67*60%)) = | Z24: =((((1000-25-X9)*AA9)-(Y9/AK8))*AL19*60%) -> 417.93289 | AA24: kg/m3
C25: =(1000-(M9*1000))/(((I28+I29)/(B29))+(I30/M14)+(I31/M15)+(I32/M16)+(I33/M17)+(I34/M18)+(I35/M19)+I36) -> 379.98756 | E25: 4. Traços
E26: DOSAGEM PARA 1 m3 - 1000 litros | K26: DOSAGEM PARA 1 BETONADA DE | O26: 25 | P26: litros
B27: =(1-F29)*M12 -> 3.08 | E27: material | G27: traço inicial | H27: t.unitário | I27: t.unit.cor. | J27: traço corr. | K27: material | M27: massa seca (kg) | N27: h(%) | O27: mat. corrig | P27: correção | T27: d) Quantidade de BRITA: | AH27: My agregados GRAUDOS proporcional
B28: =F29*M13 -> 0 | C28: =IF(J9<>0,J9,(I9/K9)) -> 380 | E28: cimento | G28: =IF(I9=0," ",(C28-G29)) -> 380 | H28: 1 | I28: =IF(I9=0," ",($M28+$P28)/($M$28+$P$28)) -> 1 | J28: =IF(I9=0," ",C25-J29) -> 379.98756 | K28: cimento | L28: =IF($K12=0," ",$K12) -> CPII E 40 | M28: =IF(I9=0," ",$G28*($O$26/1000)) -> 9.5 | AH28: proporção areia nat e art: 30/70 = (30%*2,70 + 70%2,70) = | AL28: =2.7*30%+2.7*70% -> 2.7
B29: =B27+B28 -> 3.08 | E29: aglom.2 | F29: 0 | G29: =IF(I9=0," ",F29*C28) -> 0 | J29: =IF(I9=0," ",C25*F29) -> 0 | K29: aglom.2 | L29: =IF($K13=0," ",$K13) | M29: =IF(I9=0," ",$G29*($O$26/1000)) -> 0 | T29: Qtde de B 0 = ((v°- %ar-água)-(v°- %ar-água)*%arg)*My agregado Graudo proporcional*% Brita 0
B30: =$M14*$F30 -> 1.052 | E30: ag.miúdo 1 | F30: 0.4 | G30: =IF(I9=0," ",(((1000-($M$9*1000)-$I$9)*$L$9)-($G$28/$M$12)-($G$29/$M$13))*$B$33*$F30) -> 278.62193 | H30: =IF(I9=0," ",$G30/($G$28+$G$29)) -> 0.7332156 | I30: =IF(I9=0," ",(($M30+($P30/(1+$N30)))/($M$28+$P$28+$M$29+$P$29))) -> 0.7332156 | J30: =IF(I9=0," ",$I30*$C$25) -> 278.61281 | K30: ag.miúdo 1 | L30: =IF($K14=0," ",$K14) -> AQFINA | M30: =IF(I9=0," ",$G30*($O$26/1000)) -> 6.9655482 | N30: 0 | O30: =IF($N30=" "," ",$M30*(1+$N30)) -> 6.9655482
B31: =$M15*$F31 -> 1.614 | E31: ag.miúdo 2 | F31: 0.6 | G31: =IF(I9=0," ",(((1000-($M$9*1000)-$I$9)*$L$9)-($G$28/$M$12)-($G$29/$M$13))*$B$33*$F31) -> 417.93289 | H31: =IF(I9=0," ",$G31/($G$28+$G$29)) -> 1.0998234 | I31: =IF(I9=0," ",(($M31+($P31/(1+$N31)))/($M$28+$P$28+$M$29+$P$29))) -> 1.0998234 | J31: =IF(I9=0," ",$I31*$C$25) -> 417.91922 | K31: ag.miúdo 2 | L31: =IF($K15=0," ",$K15) -> AQGROSSA | M31: =IF(I9=0," ",$G31*($O$26/1000)) -> 10.448322 | N31: 0 | O31: =IF($N31=" "," ",$M31*(1+$N31)) -> 10.448322 | T31: ex. | U31: :((1000-25-200)-((1000-25-200)*49%))*2,70*30%: | AA31: =((1000-25-X9)-((1000-25-X9)*AA9))*AL28*30% -> 324.2835 | AB31: kg/m3
B32: =$M16*$F32 -> 0 | E32: ag.miúdo 3 | F32: 0 | G32: =IF(I9=0," ",(((1000-($M$9*1000)-$I$9)*$L$9)-($G$28/$M$12)-($G$29/$M$13))*$B$33*$F32) -> 0 | H32: =IF(I9=0," ",$G32/($G$28+$G$29)) -> 0 | I32: =IF(I9=0," ",(($M32+($P32/(1+$N32)))/($M$28+$P$28+$M$29+$P$29))) -> 0 | J32: =IF(I9=0," ",$I32*$C$25) -> 0 | K32: ag.miúdo 3 | M32: =IF(I9=0," ",$G32*($O$26/1000)) -> 0
B33: =B30+B31+B32 -> 2.666 | C33: =$M17*$F33 -> 0.81 | E33: ag.graúdo 1 | F33: 0.3 | G33: =IF(I9=0," ",((((1000-($M$9*1000)-$G$36))-((1000-($M$9*1000)-$G$36)*$L$9)))*$C$36*$F33) -> 324.2835 | H33: =IF(I9=0," ",$G33/($G$28+$G$29)) -> 0.85337763 | I33: =IF(I9=0," ",(($M33+($P33/(1+$N33)))/($M$28+$P$28+$M$29+$P$29))) -> 0.85337763 | J33: =IF(I9=0," ",$I33*$C$25) -> 324.27289 | K33: ag.graúdo 1 | L33: =IF($K17=0," ",$K17) -> Brita 0 | M33: =IF(I9=0," ",$G33*($O$26/1000)) -> 8.1070875 | T33: Qtde de B 1 = ((v°- %ar-água)-(v°- %ar-água)*%arg)*My agregado Graudo proporcional*% Brita 1
C34: =$M18*$F34 -> 1.89 | E34: ag.graúdo 2 | F34: 0.7 | G34: =IF(I9=0," ",((((1000-($M$9*1000)-$G$36))-((1000-($M$9*1000)-$G$36)*$L$9)))*$C$36*$F34) -> 756.6615 | H34: =IF(I9=0," ",$G34/($G$28+$G$29)) -> 1.9912145 | I34: =IF(I9=0," ",(($M34+($P34/(1+$N34)))/($M$28+$P$28+$M$29+$P$29))) -> 1.9912145 | J34: =IF(I9=0," ",$I34*$C$25) -> 756.63674 | K34: ag.graúdo 2 | L34: =IF($K18=0," ",$K18) -> Brita 1 | M34: =IF(I9=0," ",$G34*($O$26/1000)) -> 18.916538
C35: =$M19*$F35 -> 0 | E35: ag.graúdo 3 | F35: 0 | G35: =IF(I9=0," ",((((1000-($M$9*1000)-$G$36))-((1000-($M$9*1000)-$G$36)*$L$9)))*$C$36*$F35) -> 0 | H35: =IF(I9=0," ",$G35/($G$28+$G$29)) -> 0 | I35: =IF(I9=0," ",(($M35+($P35/(1+$N35)))/($M$28+$P$28+$M$29+$P$29))) -> 0 | J35: =IF(I9=0," ",$I35*$C$25) -> 0 | K35: ag.graúdo 3 | L35: =IF($K19=0," ",$K19) | M35: =IF(I9=0," ",$G35*($O$26/1000)) -> 0 | T35: ex. | U35: ((1000-25-200)-((1000-25-200)*49%))*2,70*70% | AA35: =((1000-25-X9)-((1000-25-X9)*AA9))*AL28*70% -> 756.6615 | AB35: kg/m3
C36: =C33+C34+C35 -> 2.7 | E36: água | G36: =IF(I9=0," ",I9) -> 190 | H36: =IF(I9=0," ",$G36/($G$28+$G$29)) -> 0.5 | I36: =IF(I9=0," ",($M36+$P36+($P30-($P30/(1+$N30)))+($P31-($P31/(1+$N31)))+($P32-($P32/(1+$N32)))+($P33-($P33/(1+$N33)))+($P34-($P34/(1+$N34)))+($P35-($P35/(1+$N35)))+($P36-($P36/(1+$N36))))/($M$28+$P$28+M29+P29)) -> 0.5 | J36: =IF(I9=0," ",$I36*$C$25) -> 189.99378 | K36: água | M36: =IF(I9=0," ",$G36*($O$26/1000)) -> 4.75 | O36: =M36-(O31-M31)-(O30-M30) -> 4.75 | P36: 0
E37: aditivo 1(%) | F37: 0.005 | G37: =IF(I9=0," ",$F37*($G$28+$G$29)) -> 1.9 | J37: =IF($I$9=0," ",$F37*($J$28+$J$29)) -> 1.8999378 | K37: aditivo 1 (litro) | L37: =IF($K20=0," ",$K20) -> TM828LF | M37: =IF(I9=0," ",$G37*($O$26/1000)*1000) -> 47.5
E38: aditivo 2(%) | F38: 0.006 | G38: =IF(I9=0," ",$F38*($G$28+$G$29)) -> 2.28 | J38: =IF($I$9=0," ",$F38*($J$28+$J$29)) -> 2.2799254 | K38: aditivo 2 (litro) | L38: =IF($K21=0," ",$K21) -> TF41N | M38: =IF(I9=0," ",$G38*($O$26/1000)*1000) -> 57 | T38: e) Quantidade de aditivo:
E39: aditivo 3(%) | G39: =IF(I9=0," ",$F39*($G$28+$G$29)) -> 0 | J39: =IF($I$9=0," ",$F39*($J$28+$J$29)) -> 0 | K39: aditivo 3 (litro) | L39: =IF($K22=0," ",$K22) | M39: =IF(I9=0," ",$G39*($O$26/1000)*1000) -> 0
E40: adição 1(%) | G40: =IF(I9=0," ",$F40*($G$28+$G$29)) -> 0 | H40: =SUM(G28:G39) -> 2351.6798 | J40: =IF($I$9=0," ",$F40*($J$28+$J$29)) -> 0 | K40: adição 1 | L40: =IF($K23=0," ",$K23) | M40: =IF(I9=0," ",$G40*($O$26/1000)) -> 0 | V40: Adito 1 = Qtde de cimento * % de aditvo
E41: adição 2 | J41: =IF($I$9=0," ",$F41*($J$28+$J$29)) -> 0 | K41: adição 2 | L41: =IF($K24=0," ",$K24) | M41: =IF(I9=0," ",$J41*($O$26/1000)) -> 0 | U41: Ex.: 380*0,75% = | W41: =Y9*0.75% -> 2.85 | X41: kg/m3
...
